<sdf version='1.3'>
  <model name='powerball'>
    <link name='base_link'>
      <pose>0.000000 0.000000 0.000000 0.000000 0.000000 0.000000</pose>
      <inertial>
        <pose>0.000000 0.000000 -9.996920 0.000000 0.000000 0.000000</pose>
        <mass>1000.290000</mass>
        <inertia>
          <ixx>100.083000</ixx>
          <ixy>0.000000</ixy>
          <ixz>0.000000</ixz>
          <iyy>100.083000</iyy>
          <iyz>0.000000</iyz>
          <izz>100.010000</izz>
        </inertia>
      </inertial>
      <collision name='base_link_geom'>
        <pose>0.000000 0.000000 0.250000 0.000000 0.000000 0.000000</pose>
        <geometry>
          <box>
            <size>0.200000 0.300000 0.500000</size>
          </box>
        </geometry>
      </collision>
      <collision name='base_link_geom_arm_0_link'>
        <pose>0.000000 0.000000 0.500000 3.141590 0.000000 0.000000</pose>
        <geometry>
          <mesh>
            <scale>1.000000 1.000000 1.000000</scale>
            <uri>file://meshes/powerball0.stl</uri>
          </mesh>
        </geometry>
        <surface>
          <contact>
            <ode/>
          </contact>
          <friction>
            <ode/>
          </friction>
        </surface>
      </collision>
      <visual name='base_link_visual'>
        <pose>0.000000 0.000000 0.250000 0.000000 0.000000 0.000000</pose>
        <geometry>
          <box>
            <size>0.200000 0.300000 0.500000</size>
          </box>
        </geometry>
      </visual>
      <visual name='base_link_visualarm_0_link'>
        <pose>0.000000 0.000000 0.500000 3.141590 0.000000 0.000000</pose>
        <geometry>
          <mesh>
            <scale>1.000000 1.000000 1.000000</scale>
            <uri>file://meshes/powerball0.stl</uri>
          </mesh>
        </geometry>
        <material>
          <script>
            <name>PR2/Grey</name>
          </script>
        </material>
      </visual>
      <gravity>1</gravity>
      <velocity_decay>
        <linear>0.000000</linear>
        <angular>0.000000</angular>
      </velocity_decay>
      <self_collide>1</self_collide>
    </link>
    <link name='arm_1_link'>
      <pose>0.000000 0.000000 0.589700 3.141590 0.000000 0.000000</pose>
      <inertial>
        <pose>0.000000 0.000000 0.000000 0.000000 0.000000 0.000000</pose>
        <mass>0.293640</mass>
        <inertia>
          <ixx>0.010000</ixx>
          <ixy>0.000000</ixy>
          <ixz>0.000000</ixz>
          <iyy>0.010000</iyy>
          <iyz>0.000000</iyz>
          <izz>0.010000</izz>
        </inertia>
      </inertial>
      <collision name='arm_1_link_geom'>
        <pose>0.000000 0.000000 0.000000 0.000000 0.000000 0.000000</pose>
        <geometry>
          <mesh>
            <scale>1.000000 1.000000 1.000000</scale>
            <uri>file://meshes/powerball1.stl</uri>
          </mesh>
        </geometry>
        <surface>
          <contact>
            <ode/>
          </contact>
          <friction>
            <ode/>
          </friction>
        </surface>
      </collision>
      <visual name='arm_1_link_visual'>
        <pose>0.000000 0.000000 0.000000 0.000000 0.000000 0.000000</pose>
        <geometry>
          <mesh>
            <scale>1.000000 1.000000 1.000000</scale>
            <uri>file://meshes/powerball1.stl</uri>
          </mesh>
        </geometry>
        <material>
          <script>
            <name>PR2/Blue</name>
          </script>
        </material>
      </visual>
      <gravity>1</gravity>
      <velocity_decay>
        <linear>0.000000</linear>
        <angular>0.000000</angular>
      </velocity_decay>
      <self_collide>1</self_collide>
    </link>
    <joint name='arm_1_joint' type='revolute'>
      <child>arm_1_link</child>
      <parent>base_link</parent>
      <axis>
        <xyz>0.000000 0.000000 1.000000</xyz>
        <limit>
          <lower>-2.967100</lower>
          <upper>2.967100</upper>
        </limit>
        <dynamics>
          <damping>10.000000</damping>
        </dynamics>
      </axis>
    </joint>
    <link name='arm_2_link'>
      <pose>0.000000 0.000000 0.589700 -1.570790 0.000000 0.000000</pose>
      <inertial>
        <pose>0.000000 0.000000 0.000000 0.000000 0.000000 0.000000</pose>
        <mass>1.683110</mass>
        <inertia>
          <ixx>0.030000</ixx>
          <ixy>0.000000</ixy>
          <ixz>0.000000</ixz>
          <iyy>0.030000</iyy>
          <iyz>0.000000</iyz>
          <izz>0.030000</izz>
        </inertia>
      </inertial>
      <collision name='arm_2_link_geom'>
        <pose>0.000000 0.000000 0.000000 0.000000 0.000000 0.000000</pose>
        <geometry>
          <mesh>
            <scale>1.000000 1.000000 1.000000</scale>
            <uri>file://meshes/powerball2.stl</uri>
          </mesh>
        </geometry>
        <surface>
          <contact>
            <ode/>
          </contact>
          <friction>
            <ode/>
          </friction>
        </surface>
      </collision>
      <visual name='arm_2_link_visual'>
        <pose>0.000000 0.000000 0.000000 0.000000 0.000000 0.000000</pose>
        <geometry>
          <mesh>
            <scale>1.000000 1.000000 1.000000</scale>
            <uri>file://meshes/powerball2.stl</uri>
          </mesh>
        </geometry>
        <material>
          <script>
            <name>PR2/Grey</name>
          </script>
        </material>
      </visual>
      <gravity>1</gravity>
      <velocity_decay>
        <linear>0.000000</linear>
        <angular>0.000000</angular>
      </velocity_decay>
      <self_collide>1</self_collide>
    </link>
    <joint name='arm_2_joint' type='revolute'>
      <child>arm_2_link</child>
      <parent>arm_1_link</parent>
      <axis>
        <xyz>0.000000 -1.000000 -0.000004</xyz>
        <limit>
          <lower>-2.967100</lower>
          <upper>2.967100</upper>
        </limit>
        <dynamics>
          <damping>10.000000</damping>
        </dynamics>
      </axis>
    </joint>
    <link name='arm_3_link'>
      <pose>0.000000 -0.000001 0.939700 1.570800 0.000000 0.000000</pose>
      <inertial>
        <pose>0.000000 0.000000 0.000000 0.000000 0.000000 0.000000</pose>
        <mass>2.100000</mass>
        <inertia>
          <ixx>0.030000</ixx>
          <ixy>0.000000</ixy>
          <ixz>0.000000</ixz>
          <iyy>0.030000</iyy>
          <iyz>0.000000</iyz>
          <izz>0.030000</izz>
        </inertia>
      </inertial>
      <collision name='arm_3_link_geom'>
        <pose>0.000000 0.000000 0.000000 0.000000 0.000000 0.000000</pose>
        <geometry>
          <mesh>
            <scale>1.000000 1.000000 1.000000</scale>
            <uri>file://meshes/powerball3.stl</uri>
          </mesh>
        </geometry>
        <surface>
          <contact>
            <ode/>
          </contact>
          <friction>
            <ode/>
          </friction>
        </surface>
      </collision>
      <visual name='arm_3_link_visual'>
        <pose>0.000000 0.000000 0.000000 0.000000 0.000000 0.000000</pose>
        <geometry>
          <mesh>
            <scale>1.000000 1.000000 1.000000</scale>
            <uri>file://meshes/powerball3.stl</uri>
          </mesh>
        </geometry>
        <material>
          <script>
            <name>PR2/Blue</name>
          </script>
        </material>
      </visual>
      <gravity>1</gravity>
      <velocity_decay>
        <linear>0.000000</linear>
        <angular>0.000000</angular>
      </velocity_decay>
      <self_collide>1</self_collide>
    </link>
    <joint name='arm_3_joint' type='revolute'>
      <child>arm_3_link</child>
      <parent>arm_2_link</parent>
      <axis>
        <xyz>0.000000 1.000000 0.000001</xyz>
        <limit>
          <lower>-2.967100</lower>
          <upper>2.967100</upper>
        </limit>
        <dynamics>
          <damping>5.000000</damping>
        </dynamics>
      </axis>
    </joint>
    <link name='arm_4_link'>
      <pose>0.000000 -0.000001 0.939700 -3.141590 -0.000000 3.141590</pose>
      <inertial>
        <pose>0.000000 0.000000 0.000000 0.000000 0.000000 0.000000</pose>
        <mass>1.683110</mass>
        <inertia>
          <ixx>0.030000</ixx>
          <ixy>0.000000</ixy>
          <ixz>0.000000</ixz>
          <iyy>0.030000</iyy>
          <iyz>0.000000</iyz>
          <izz>0.030000</izz>
        </inertia>
      </inertial>
      <collision name='arm_4_link_geom'>
        <pose>0.000000 0.000000 0.000000 0.000000 0.000000 0.000000</pose>
        <geometry>
          <mesh>
            <scale>1.000000 1.000000 1.000000</scale>
            <uri>file://meshes/powerball4.stl</uri>
          </mesh>
        </geometry>
        <surface>
          <contact>
            <ode/>
          </contact>
          <friction>
            <ode/>
          </friction>
        </surface>
      </collision>
      <visual name='arm_4_link_visual'>
        <pose>0.000000 0.000000 0.000000 0.000000 0.000000 0.000000</pose>
        <geometry>
          <mesh>
            <scale>1.000000 1.000000 1.000000</scale>
            <uri>file://meshes/powerball4.stl</uri>
          </mesh>
        </geometry>
        <material>
          <script>
            <name>PR2/Grey</name>
          </script>
        </material>
      </visual>
      <gravity>1</gravity>
      <velocity_decay>
        <linear>0.000000</linear>
        <angular>0.000000</angular>
      </velocity_decay>
      <self_collide>1</self_collide>
    </link>
    <joint name='arm_4_joint' type='revolute'>
      <child>arm_4_link</child>
      <parent>arm_3_link</parent>
      <axis>
        <xyz>-0.000000 -0.000003 -1.000000</xyz>
        <limit>
          <lower>-2.967100</lower>
          <upper>2.967100</upper>
        </limit>
        <dynamics>
          <damping>5.000000</damping>
        </dynamics>
      </axis>
    </joint>
    <link name='arm_5_link'>
      <pose>0.000000 0.005000 1.244600 -1.570790 -0.000000 3.141590</pose>
      <inertial>
        <pose>0.000000 0.000000 0.000000 0.000000 0.000000 0.000000</pose>
        <mass>0.807000</mass>
        <inertia>
          <ixx>0.030000</ixx>
          <ixy>0.000000</ixy>
          <ixz>0.000000</ixz>
          <iyy>0.030000</iyy>
          <iyz>0.000000</iyz>
          <izz>0.030000</izz>
        </inertia>
      </inertial>
      <collision name='arm_5_link_geom'>
        <pose>0.000000 0.000000 0.000000 0.000000 0.000000 0.000000</pose>
        <geometry>
          <mesh>
            <scale>1.000000 1.000000 1.000000</scale>
            <uri>file://meshes/powerball5.stl</uri>
          </mesh>
        </geometry>
        <surface>
          <contact>
            <ode/>
          </contact>
          <friction>
            <ode/>
          </friction>
        </surface>
      </collision>
      <visual name='arm_5_link_visual'>
        <pose>0.000000 0.000000 0.000000 0.000000 0.000000 0.000000</pose>
        <geometry>
          <mesh>
            <scale>1.000000 1.000000 1.000000</scale>
            <uri>file://meshes/powerball5.stl</uri>
          </mesh>
        </geometry>
        <material>
          <script>
            <name>PR2/Blue</name>
          </script>
        </material>
      </visual>
      <gravity>1</gravity>
      <velocity_decay>
        <linear>0.000000</linear>
        <angular>0.000000</angular>
      </velocity_decay>
      <self_collide>1</self_collide>
    </link>
    <joint name='arm_5_joint' type='revolute'>
      <child>arm_5_link</child>
      <parent>arm_4_link</parent>
      <axis>
        <xyz>0.000003 1.000000 -0.000006</xyz>
        <limit>
          <lower>-2.967100</lower>
          <upper>2.967100</upper>
        </limit>
        <dynamics>
          <damping>5.000000</damping>
        </dynamics>
      </axis>
    </joint>
    <link name='arm_6_link'>
      <pose>0.000000 0.005000 1.244600 -3.141590 -0.000000 3.141590</pose>
      <inertial>
        <pose>0.000000 0.000000 -0.050520 0.000000 0.000000 0.000000</pose>
        <mass>2.019000</mass>
        <inertia>
          <ixx>1.018670</ixx>
          <ixy>0.000000</ixy>
          <ixz>0.000000</ixz>
          <iyy>1.018670</iyy>
          <iyz>0.000000</iyz>
          <izz>1.010000</izz>
        </inertia>
      </inertial>
      <collision name='arm_6_link_geom'>
        <pose>0.000000 0.000000 0.000000 0.000000 0.000000 0.000000</pose>
        <geometry>
          <mesh>
            <scale>1.000000 1.000000 1.000000</scale>
            <uri>file://meshes/powerball6.stl</uri>
          </mesh>
        </geometry>
        <surface>
          <contact>
            <ode/>
          </contact>
          <friction>
            <ode/>
          </friction>
        </surface>
      </collision>
      <collision name='arm_6_link_geom_gripper_base_link'>
        <pose>0.000000 0.000000 -0.085000 3.141500 0.000000 0.000000</pose>
        <geometry>
          <mesh>
            <scale>1.000000 1.000000 1.000000</scale>
            <uri>file://meshes/WSG50_110.stl</uri>
          </mesh>
        </geometry>
        <surface>
          <contact>
            <ode/>
          </contact>
          <friction>
            <ode/>
          </friction>
        </surface>
      </collision>
      <visual name='arm_6_link_visual'>
        <pose>0.000000 0.000000 0.000000 0.000000 0.000000 0.000000</pose>
        <geometry>
          <mesh>
            <scale>1.000000 1.000000 1.000000</scale>
            <uri>file://meshes/powerball6.stl</uri>
          </mesh>
        </geometry>
        <material>
          <script>
            <name>PR2/Grey</name>
          </script>
        </material>
      </visual>
      <visual name='arm_6_link_visualgripper_base_link'>
        <pose>0.000000 0.000000 -0.085000 3.141500 0.000000 0.000000</pose>
        <geometry>
          <mesh>
            <scale>1.000000 1.000000 1.000000</scale>
            <uri>file://meshes/WSG50_110.stl</uri>
          </mesh>
        </geometry>
        <material>
          <script>
            <name>Gazebo/Grey</name>
          </script>
        </material>
      </visual>
      <velocity_decay>
        <linear>0.000000</linear>
        <angular>0.000000</angular>
      </velocity_decay>
      <gravity>1</gravity>
      <velocity_decay>
        <linear>0.000000</linear>
        <angular>0.000000</angular>
      </velocity_decay>
      <self_collide>0</self_collide>
    </link>
    <joint name='arm_6_joint' type='revolute'>
      <child>arm_6_link</child>
      <parent>arm_5_link</parent>
      <axis>
        <xyz>0.000000 0.000003 1.000000</xyz>
        <limit>
          <lower>-2.967100</lower>
          <upper>2.967100</upper>
        </limit>
        <dynamics>
          <damping>5.000000</damping>
        </dynamics>
      </axis>
    </joint>
    <link name='gripper_left'>
      <pose>0.000000 0.005000 1.329600 -0.000090 -0.000000 3.141590</pose>
      <inertial>
        <pose>0.000000 0.000000 0.012000 0.000000 0.000000 0.000000</pose>
        <mass>0.200000</mass>
        <inertia>
          <ixx>2.000060</ixx>
          <ixy>0.000000</ixy>
          <ixz>0.000000</ixz>
          <iyy>2.000060</iyy>
          <iyz>0.000000</iyz>
          <izz>2.000000</izz>
        </inertia>
      </inertial>
      <collision name='gripper_left_geom'>
        <pose>0.000000 0.000000 0.000000 0.000000 0.000000 0.000000</pose>
        <geometry>
          <mesh>
            <scale>0.001000 0.001000 0.001000</scale>
            <uri>file://meshes/GUIDE_WSG50_110.stl</uri>
          </mesh>
        </geometry>
        <surface>
          <contact>
            <ode/>
          </contact>
          <friction>
            <ode/>
          </friction>
        </surface>
      </collision>
      <collision name='gripper_left_geom_finger_left'>
        <pose>0.000000 0.000000 0.024000 0.000000 0.000000 0.000000</pose>
        <geometry>
          <mesh>
            <scale>0.001000 0.001000 0.001000</scale>
            <uri>file://meshes/WSG-FMF.stl</uri>
          </mesh>
        </geometry>
        <surface>
          <contact>
            <ode/>
          </contact>
          <friction>
            <ode/>
          </friction>
        </surface>
      </collision>
      <visual name='gripper_left_visual'>
        <pose>0.000000 0.000000 0.000000 0.000000 0.000000 0.000000</pose>
        <geometry>
          <mesh>
            <scale>0.001000 0.001000 0.001000</scale>
            <uri>file://meshes/GUIDE_WSG50_110.stl</uri>
          </mesh>
        </geometry>
        <material>
          <script>
            <name>Gazebo/Blue</name>
          </script>
        </material>
      </visual>
      <visual name='gripper_left_visualfinger_left'>
        <pose>0.000000 0.000000 0.024000 0.000000 0.000000 0.000000</pose>
        <geometry>
          <mesh>
            <scale>0.001000 0.001000 0.001000</scale>
            <uri>file://meshes/WSG-FMF.stl</uri>
          </mesh>
        </geometry>
        <material>
          <script>
            <name>Gazebo/Blue</name>
          </script>
        </material>
      </visual>
      <velocity_decay>
        <linear>0.000000</linear>
        <angular>0.000000</angular>
      </velocity_decay>
      <gravity>1</gravity>
      <velocity_decay>
        <linear>0.000000</linear>
        <angular>0.000000</angular>
      </velocity_decay>
      <self_collide>0</self_collide>
    </link>
    <joint name='base_joint_gripper_left' type='prismatic'>
      <child>gripper_left</child>
      <parent>arm_6_link</parent>
      <axis>
        <xyz>-1.000000 0.000003 0.000000</xyz>
        <limit>
          <lower>-0.055000</lower>
          <upper>-0.004000</upper>
        </limit>
        <dynamics>
          <damping>100.000000</damping>
        </dynamics>
      </axis>
    </joint>
    <link name='gripper_right'>
      <pose>0.000000 0.005000 1.329600 0.000090 0.000000 -0.000005</pose>
      <inertial>
        <pose>0.000000 0.000000 0.012000 0.000000 0.000000 0.000000</pose>
        <mass>0.200000</mass>
        <inertia>
          <ixx>2.000060</ixx>
          <ixy>0.000000</ixy>
          <ixz>0.000000</ixz>
          <iyy>2.000060</iyy>
          <iyz>0.000000</iyz>
          <izz>2.000000</izz>
        </inertia>
      </inertial>
      <collision name='gripper_right_geom'>
        <pose>0.000000 0.000000 0.000000 0.000000 0.000000 0.000000</pose>
        <geometry>
          <mesh>
            <scale>0.001000 0.001000 0.001000</scale>
            <uri>file://meshes/GUIDE_WSG50_110.stl</uri>
          </mesh>
        </geometry>
        <surface>
          <contact>
            <ode/>
          </contact>
          <friction>
            <ode/>
          </friction>
        </surface>
      </collision>
      <collision name='gripper_right_geom_finger_right'>
        <pose>0.000000 0.000000 0.024000 0.000000 0.000000 0.000000</pose>
        <geometry>
          <mesh>
            <scale>0.001000 0.001000 0.001000</scale>
            <uri>file://meshes/WSG-FMF.stl</uri>
          </mesh>
        </geometry>
        <surface>
          <contact>
            <ode/>
          </contact>
          <friction>
            <ode/>
          </friction>
        </surface>
      </collision>
      <visual name='gripper_right_visual'>
        <pose>0.000000 0.000000 0.000000 0.000000 0.000000 0.000000</pose>
        <geometry>
          <mesh>
            <scale>0.001000 0.001000 0.001000</scale>
            <uri>file://meshes/GUIDE_WSG50_110.stl</uri>
          </mesh>
        </geometry>
        <material>
          <script>
            <name>Gazebo/White</name>
          </script>
        </material>
      </visual>
      <visual name='gripper_right_visualfinger_right'>
        <pose>0.000000 0.000000 0.024000 0.000000 0.000000 0.000000</pose>
        <geometry>
          <mesh>
            <scale>0.001000 0.001000 0.001000</scale>
            <uri>file://meshes/WSG-FMF.stl</uri>
          </mesh>
        </geometry>
        <material>
          <script>
            <name>Gazebo/White</name>
          </script>
        </material>
      </visual>
      <velocity_decay>
        <linear>0.000000</linear>
        <angular>0.000000</angular>
      </velocity_decay>
      <gravity>1</gravity>
      <velocity_decay>
        <linear>0.000000</linear>
        <angular>0.000000</angular>
      </velocity_decay>
      <self_collide>0</self_collide>
    </link>
    <joint name='base_joint_gripper_right' type='prismatic'>
      <child>gripper_right</child>
      <parent>arm_6_link</parent>
      <axis>
        <xyz>-1.000000 0.000005 0.000000</xyz>
        <limit>
          <lower>0.004000</lower>
          <upper>0.055000</upper>
        </limit>
        <dynamics>
          <damping>100.000000</damping>
        </dynamics>
      </axis>
    </joint>
    <static>0</static>
    <plugin name='gazebo_ros_controller_manager' filename='libgazebo_ros_controller_manager.so'>
      <alwaysOn>1</alwaysOn>
      <updateRate>1000.0</updateRate>
    </plugin>
    <plugin name='gazebo_ros_power_monitor_controller' filename='libgazebo_ros_power_monitor.so'>
      <alwaysOn>1</alwaysOn>
      <updateRate>1.0</updateRate>
      <timeout>5</timeout>
      <powerStateTopic>power_state</powerStateTopic>
      <powerStateRate>10.0</powerStateRate>
      <fullChargeCapacity>87.78</fullChargeCapacity>
      <dischargeRate>-474</dischargeRate>
      <chargeRate>525</chargeRate>
      <dischargeVoltage>15.52</dischargeVoltage>
      <chargeVoltage>16.41</chargeVoltage>
    </plugin>
    <pose>0.000000 0.000000 0.000000 0.000000 0.000000 0.000000</pose>
  </model>
</sdf>
